<?xml version="1.0" encoding="utf-8"?>
<!-- This URDF was automatically created by SolidWorks to URDF Exporter! Originally created by Stephen Brawner (brawner@gmail.com) 
     Commit Version: 1.6.0-1-g15f4949  Build Version: 1.6.7594.29634
     For more information, please see http://wiki.ros.org/sw_urdf_exporter -->


<robot
  name="dog">


  <link name="base">
    <visual>
      <origin rpy="0 0 0" xyz="0 0 0"/>
      <geometry>
        <box size="0.001 0.001 0.001"/>
      </geometry>
    </visual>
  </link>


  <joint name="floating_base" type="fixed">
    <origin rpy="0 0 0" xyz="0 0 0"/>
    <parent link="base"/>
    <child link="trunk"/>
  </joint>


  <link
    name="trunk">
    <inertial>
      <origin
        xyz="-5.5712935408965E-05 3.71480624039577E-13 0.00963070928833742"
        rpy="0 0 0" />
      <mass
        value="0.235951381641952" />
      <inertia
        ixx="0.0003476"
        ixy="0.0000040"
        ixz="0.0000000"
        iyy="0.0020087"
        iyz="0.0000000"
        izz="0.0021662" />
    </inertial>
    <visual>
      <origin
        xyz="0 0 0"
        rpy="0 0 0" />
      <geometry>
        <mesh
          filename="package://dog/meshes/trunk.STL" />
      </geometry>
    </visual>
    <collision>
      <origin
        xyz="0 0 0.01"
        rpy="0 0 0" />
      <geometry>
        <box size="0.265 0.1095 0.07"/>
      </geometry>
    </collision>
  </link>


  <link
    name="FR_hip">
    <inertial>
      <origin
        xyz="-0.0271160597941583 -0.00273386087751526 -0.00957111587003934"
        rpy="0 0 0" />
      <mass
        value="0.0930432999822988" />
      <inertia
        ixx="0.0000254"
        ixy="0.0000006"
        ixz="-0.0000002"
        iyy="0.0000283"
        iyz="0.0000000"
        izz="0.0000174" />
    </inertial>
    <visual>
      <origin
        xyz="0 0 0"
        rpy="0 0 0" />
      <geometry>
        <mesh
          filename="package://dog/meshes/FR_hip.STL" />
      </geometry>
    </visual>
    <collision>
      <origin
        xyz="-0.026 -0.006 -0.01"
        rpy="0 0 0" />
      <geometry>
        <box size="0.0435 0.042 0.0565"/>
      </geometry>
    </collision>
  </link>


  <joint
    name="FR_hip_joint"
    type="revolute">
    <origin
      xyz="0.1305 -0.03923 0.019"
      rpy="0 0 0" />
    <parent
      link="trunk" />
    <child
      link="FR_hip" />
    <axis
      xyz="1 0 0" />
    <dynamics damping="0.01" friction="0.2"/>
    <limit
      lower="-0.785398"
      upper="0.785398"
      effort="1000"
      velocity="100" />
  </joint>


  <link
    name="FR_thigh">
    <inertial>
      <origin
        xyz="0.00124222754552428 -0.0315599752141602 -0.03348350284451"
        rpy="0 0 0" />
      <mass
        value="0.170209085091772" />
      <inertia
        ixx="0.0002384"
        ixy="0.0000002"
        ixz="0.0000146"
        iyy="0.0002199"
        iyz="-0.0000108"
        izz="0.0000511" />
    </inertial>
    <visual>
      <origin
        xyz="0 0 0"
        rpy="0 0 0" />
      <geometry>
        <mesh
          filename="package://dog/meshes/FR_thigh.STL" />
      </geometry>
    </visual>
    <collision>
      <origin
        xyz="0 -0.035 -0.043"
        rpy="0 0 0" />
      <geometry>
        <box size="0.03 0.03675 0.13136"/>
      </geometry>
    </collision>
  </link>


  <joint
    name="FR_thigh_joint"
    type="revolute">
    <origin
      xyz="-0.02585 -0.024 -0.01"
      rpy="0 0 0" />
    <parent
      link="FR_hip" />
    <child
      link="FR_thigh" />
    <axis
      xyz="0 1 0" />
    <dynamics damping="0.01" friction="0.2"/>
    <limit
      lower="-1.396263"
      upper="1.396263"
      effort="1000"
      velocity="100" />
  </joint>


  <link
    name="FR_calf">
    <inertial>
      <origin
        xyz="0.000559693141303802 -0.027523524437577 -0.0254332634827794"
        rpy="0 0 0" />
      <mass
        value="0.116808458724696" />
      <inertia
        ixx="0.0001539"
        ixy="-0.0000002"
        ixz="0.0000046"
        iyy="0.0001510"
        iyz="0.0000024"
        izz="0.0000160" />
    </inertial>
    <visual>
      <origin
        xyz="0 0 0"
        rpy="0 0 0" />
      <geometry>
        <mesh
          filename="package://dog/meshes/FR_calf.STL" />
      </geometry>
    </visual>
    <collision>
      <origin
        xyz="0.005 -0.026 -0.046"
        rpy="0 0 0" />
      <geometry>
        <box size="0.02 0.02 0.13"/>
      </geometry>
    </collision>
  </link>


  <joint
    name="FR_calf_joint"
    type="revolute">
    <origin
      xyz="0.03 -0.0081 -0.10725"
      rpy="0 0 0" />
    <parent
      link="FR_thigh" />
    <child
      link="FR_calf" />
    <axis
      xyz="0 1 0" />
    <dynamics damping="0.01" friction="0.2"/>
    <limit
      lower="0.0"
      upper="1.221730"
      effort="1000"
      velocity="100" />
  </joint>


  <link
    name="FR_foot">
    <inertial>
      <origin
        xyz="-0.0065101 0.0000000 -0.0064928"
        rpy="0 0 0" />
      <mass
        value="0.00854471522743822" />
      <inertia
        ixx="0.0000011"
        ixy="0.0000000"
        ixz="0.0000003"
        iyy="0.0000011"
        iyz="0.0000000"
        izz="0.0000011" />
    </inertial>
    <visual>
      <origin
        xyz="0 0 0"
        rpy="0 0 0" />
      <geometry>
        <mesh
          filename="package://dog/meshes/FR_foot.STL" />
      </geometry>
    </visual>
    <collision>
      <origin
        xyz="0 0 0"
        rpy="0 0 0" />
      <geometry>
        <sphere radius="0.02"/>
      </geometry>
    </collision>
  </link>


  <joint
    name="FR_foot_fixed"
    type="fixed">
    <origin
      xyz="-9.305E-05 -0.0261 -0.1184"
      rpy="0 0 0" />
    <parent
      link="FR_calf" />
    <child
      link="FR_foot" />
  </joint>


  <link
    name="FL_hip">
    <inertial>
      <origin
        xyz="-0.0271160597941604 0.00273386087822203 -0.00971329475772498"
        rpy="0 0 0" />
      <mass
        value="0.0930432999822986" />
      <inertia
        ixx="0.0000254"
        ixy="-0.0000006"
        ixz="-0.0000003"
        iyy="0.0000283"
        iyz="0.0000001"
        izz="0.0000174" />
    </inertial>
    <visual>
      <origin
        xyz="0 0 0"
        rpy="0 0 0" />
      <geometry>
        <mesh
          filename="package://dog/meshes/FL_hip.STL" />
      </geometry>
    </visual>
    <collision>
      <origin
        xyz="-0.026 0.006 -0.01"
        rpy="0 0 0" />
      <geometry>
        <box size="0.0435 0.042 0.0565"/>
      </geometry>
    </collision>
  </link>


  <joint
    name="FL_hip_joint"
    type="revolute">
    <origin
      xyz="0.1305 0.03877 0.019"
      rpy="0 0 0" />
    <parent
      link="trunk" />
    <child
      link="FL_hip" />
    <axis
      xyz="1 0 0" />
    <dynamics damping="0.01" friction="0.2"/>
    <limit
      lower="-0.785398"
      upper="0.785398"
      effort="1000"
      velocity="100" />
  </joint>


  <link
    name="FL_thigh">
    <inertial>
      <origin
        xyz="0.00124223302167603 0.0315599526703868 -0.0334834657647185"
        rpy="0 0 0" />
      <mass
        value="0.170208840232432" />
      <inertia
        ixx="0.0002384"
        ixy="-0.0000002"
        ixz="0.0000146"
        iyy="0.0002199"
        iyz="0.0000108"
        izz="0.0000511" />
    </inertial>
    <visual>
      <origin
        xyz="0 0 0"
        rpy="0 0 0" />
      <geometry>
        <mesh
          filename="package://dog/meshes/FL_thigh.STL" />
      </geometry>
    </visual>
    <collision>
      <origin
        xyz="0 0.035 -0.043"
        rpy="0 0 0" />
      <geometry>
        <box size="0.03 0.03675 0.13136"/>
      </geometry>
    </collision>
  </link>


  <joint
    name="FL_thigh_joint"
    type="revolute">
    <origin
      xyz="-0.02585 0.024 -0.010445"
      rpy="0 0 0" />
    <parent
      link="FL_hip" />
    <child
      link="FL_thigh" />
    <axis
      xyz="0 1 0" />
    <dynamics damping="0.01" friction="0.2"/>
    <limit
      lower="-1.396263"
      upper="1.396263"
      effort="1000"
      velocity="100" />
  </joint>


  <link
    name="FL_calf">
    <inertial>
      <origin
        xyz="0.000559693152459434 0.0275235244058344 -0.0255477545929418"
        rpy="0 0 0" />
      <mass
        value="0.116808458234386" />
      <inertia
        ixx="0.0001544" ixy="0.0000002" ixz="0.0000046" 
        iyy="0.0001516"iyz="-0.0000024"izz="0.0000160" />
    </inertial>
    <visual>
      <origin
        xyz="0 0 0"
        rpy="0 0 0" />
      <geometry>
        <mesh
          filename="package://dog/meshes/FL_calf.STL" />
      </geometry>
    </visual>
    <collision>
      <origin
        xyz="0.005 0.026 -0.046"
        rpy="0 0 0" />
      <geometry>
        <box size="0.02 0.02 0.13"/>
      </geometry>
    </collision>
  </link>


  <joint
    name="FL_calf_joint"
    type="revolute">
    <origin
      xyz="0.03 0.0081 -0.107"
      rpy="0 0 0" />
    <parent
      link="FL_thigh" />
    <child
      link="FL_calf" />
    <axis
      xyz="0 1 0" />
    <dynamics damping="0.01" friction="0.2"/>
    <limit
      lower="0.0"
      upper="1.221730"
      effort="1000"
      velocity="100" />
  </joint>


  <link
    name="FL_foot">
    <inertial>
      <origin
        xyz="-0.0065101 0.0000000 -0.0064928"
        rpy="0 0 0" />
      <mass
        value="0.0085447152274383" />
      <inertia
        ixx="0.0000011"
        ixy="0.0000000"
        ixz="0.0000003"
        iyy="0.0000011"
        iyz="0.0000000"
        izz="0.0000011" />
    </inertial>
    <visual>
      <origin
        xyz="0 0 0"
        rpy="0 0 0" />
      <geometry>
        <mesh
          filename="package://dog/meshes/FL_foot.STL" />
      </geometry>
    </visual>
    <collision>
      <origin
        xyz="0 0 0"
        rpy="0 0 0" />
      <geometry>
        <sphere radius="0.02"/>
      </geometry>
    </collision>
  </link>


  <joint
    name="FL_foot_fixed"
    type="fixed">
    <origin
      xyz="-9.305E-05 0.0261 -0.11865"
      rpy="0 0 0" />
    <parent
      link="FL_calf" />
    <child
      link="FL_foot" />
  </joint>


  <link
    name="RR_hip">
    <inertial>
      <origin
        xyz="0.0271159993235821 -0.00273386087762806 -0.00957111587008197"
        rpy="0 0 0" />
      <mass
        value="0.0930432999822872" />
      <inertia
        ixx="0.0000254"
        ixy="-0.0000006"
        ixz="0.0000002"
        iyy="0.0000283"
        iyz="0.0000000"
        izz="0.0000174" />
    </inertial>
    <visual>
      <origin
        xyz="0 0 0"
        rpy="0 0 0" />
      <geometry>
        <mesh
          filename="package://dog/meshes/RR_hip.STL" />
      </geometry>
    </visual>
    <collision>
      <origin
        xyz="0.026 -0.006 -0.01"
        rpy="0 0 0" />
      <geometry>
        <box size="0.0435 0.042 0.0565"/>
      </geometry>
    </collision>
  </link>


  <joint
    name="RR_hip_joint"
    type="revolute">
    <origin
      xyz="-0.1305 -0.03877 0.019"
      rpy="0 0 0" />
    <parent
      link="trunk" />
    <child
      link="RR_hip" />
    <axis
      xyz="1 0 0" />
    <dynamics damping="0.01" friction="0.2"/>
    <limit
      lower="-0.785398"
      upper="0.785398"
      effort="1000"
      velocity="100" />
  </joint>


  <link
    name="RR_thigh">
    <inertial>
      <origin
        xyz="0.00124222754552366 -0.0315599752141685 -0.0334835028445148"
        rpy="0 0 0" />
      <mass
        value="0.170209085091772" />
      <inertia
        ixx="0.0002384"
        ixy="0.0000002"
        ixz="0.0000146"
        iyy="0.0002199"
        iyz="-0.0000108"
        izz="0.0000511" />
    </inertial>
    <visual>
      <origin
        xyz="0 0 0"
        rpy="0 0 0" />
      <geometry>
        <mesh
          filename="package://dog/meshes/RR_thigh.STL" />
      </geometry>
    </visual>
    <collision>
      <origin
        xyz="0 -0.035 -0.043"
        rpy="0 0 0" />
      <geometry>
        <box size="0.03 0.03675 0.13136"/>
      </geometry>
    </collision>
  </link>


  <joint
    name="RR_thigh_joint"
    type="revolute">
    <origin
      xyz="0.02585 -0.024 -0.01"
      rpy="0 0 0" />
    <parent
      link="RR_hip" />
    <child
      link="RR_thigh" />
    <axis
      xyz="0 1 0" />
    <dynamics damping="0.01" friction="0.2"/>
    <limit
      lower="-1.396263"
      upper="1.396263"
      effort="1000"
      velocity="100" />
  </joint>


  <link
    name="RR_calf">
    <inertial>
      <origin
        xyz="0.000559693141302994 -0.0275235244375864 -0.0254332634827802"
        rpy="0 0 0" />
      <mass
        value="0.116808458724706" />
      <inertia
        ixx="0.0001539"
        ixy="-0.0000002"
        ixz="0.0000046"
        iyy="0.0001510"
        iyz="0.0000024"
        izz="0.0000160" />
    </inertial>
    <visual>
      <origin
        xyz="0 0 0"
        rpy="0 0 0" />
      <geometry>
        <mesh
          filename="package://dog/meshes/RR_calf.STL" />
      </geometry>
    </visual>
    <collision>
      <origin
        xyz="0.005 -0.026 -0.046"
        rpy="0 0 0" />
      <geometry>
        <box size="0.02 0.02 0.13"/>
      </geometry>
    </collision>
  </link>


  <joint
    name="RR_calf_joint"
    type="revolute">
    <origin
      xyz="0.03 -0.0081 -0.10725"
      rpy="0 0 0" />
    <parent
      link="RR_thigh" />
    <child
      link="RR_calf" />
    <axis
      xyz="0 1 0" />
    <dynamics damping="0.01" friction="0.2"/>
    <limit
      lower="0.0"
      upper="1.221730"
      effort="1000"
      velocity="100" />
  </joint>


  <link
    name="RR_foot">
    <inertial>
      <origin
        xyz="-0.0065101 0.0000000 -0.0064928"
        rpy="0 0 0" />
      <mass
        value="0.00854471522743826" />
      <inertia
        ixx="0.0000011"
        ixy="0.0000000"
        ixz="0.0000003"
        iyy="0.0000011"
        iyz="0.0000000"
        izz="0.0000011" />
    </inertial>
    <visual>
      <origin
        xyz="0 0 0"
        rpy="0 0 0" />
      <geometry>
        <mesh
          filename="package://dog/meshes/RR_foot.STL" />
      </geometry>
    </visual>
    <collision>
      <origin
        xyz="0 0 0"
        rpy="0 0 0" />
      <geometry>
        <sphere radius="0.02"/>
      </geometry>
    </collision>
  </link>


  <joint
    name="RR_foot_fixed"
    type="fixed">
    <origin
      xyz="-9.305E-05 -0.0261 -0.1184"
      rpy="0 0 0" />
    <parent
      link="RR_calf" />
    <child
      link="RR_foot" />
  </joint>


  <link
    name="RL_hip">
    <inertial>
      <origin
        xyz="0.027115999323585 0.00273386087824529 -0.00957111587007775"
        rpy="0 0 0" />
      <mass
        value="0.0930432999822988" />
      <inertia
        ixx="0.0000254"
        ixy="0.0000006"
        ixz="0.0000002"
        iyy="0.0000283"
        iyz="0.0000000"
        izz="0.0000174" />
    </inertial>
    <visual>
      <origin
        xyz="0 0 0"
        rpy="0 0 0" />
      <geometry>
        <mesh
          filename="package://dog/meshes/RL_hip.STL" />
      </geometry>
    </visual>
    <collision>
      <origin
        xyz="0.026 0.006 -0.01"
        rpy="0 0 0" />
      <geometry>
        <box size="0.0435 0.042 0.0565"/>
      </geometry>
    </collision>
  </link>


  <joint
    name="RL_hip_joint"
    type="revolute">
    <origin
      xyz="-0.1305 0.03923 0.019"
      rpy="0 0 0" />
    <parent
      link="trunk" />
    <child
      link="RL_hip" />
    <axis
      xyz="1 0 0" />
    <dynamics damping="0.01" friction="0.2"/>
    <limit
      lower="-0.785398"
      upper="0.785398"
      effort="1000"
      velocity="100" />
  </joint>


  <link
    name="RL_thigh">
    <inertial>
      <origin
        xyz="0.00124223302167593 0.0315599526703872 -0.0334834657647154"
        rpy="0 0 0" />
      <mass
        value="0.170208840232442" />
      <inertia
        ixx="0.0002384"
        ixy="-0.0000002"
        ixz="0.0000146"
        iyy="0.0002199"
        iyz="0.0000108"
        izz="0.0000511" />
    </inertial>
    <visual>
      <origin
        xyz="0 0 0"
        rpy="0 0 0" />
      <geometry>
        <mesh
          filename="package://dog/meshes/RL_thigh.STL" />
      </geometry>
    </visual>
    <collision>
      <origin
        xyz="0 0.035 -0.043"
        rpy="0 0 0" />
      <geometry>
        <box size="0.03 0.03675 0.13136"/>
      </geometry>
    </collision>
  </link>


  <joint
    name="RL_thigh_joint"
    type="revolute">
    <origin
      xyz="0.02585 0.024 -0.01"
      rpy="0 0 0" />
    <parent
      link="RL_hip" />
    <child
      link="RL_thigh" />
    <axis
      xyz="0 1 0" />
    <dynamics damping="0.01" friction="0.2"/>
    <limit
      lower="-1.396263"
      upper="1.396263"
      effort="1000"
      velocity="100" />
  </joint>


  <link
    name="RL_calf">
    <inertial>
      <origin
        xyz="0.000559693152459951 0.0275232460794471 -0.0255477545929381"
        rpy="0 0 0" />
      <mass
        value="0.116808458234397" />
      <inertia
        ixx="0.0001544"
        ixy="0.0000002"
        ixz="0.0000046"
        iyy="0.0001516"
        iyz="-0.0000024"
        izz="0.0000160" />
    </inertial>
    <visual>
      <origin
        xyz="0 0 0"
        rpy="0 0 0" />
      <geometry>
        <mesh
          filename="package://dog/meshes/RL_calf.STL" />
      </geometry>
    </visual>
    <collision>
      <origin
        xyz="0.005 0.026 -0.046"
        rpy="0 0 0" />
      <geometry>
        <box size="0.02 0.02 0.13"/>
      </geometry>
    </collision>
  </link>


  <joint
    name="RL_calf_joint"
    type="revolute">
    <origin
      xyz="0.03 0.0081 -0.107"
      rpy="0 0 0" />
    <parent
      link="RL_thigh" />
    <child
      link="RL_calf" />
    <axis
      xyz="0 1 0" />
    <dynamics damping="0.01" friction="0.2"/>
    <limit
      lower="0.0"
      upper="1.221730"
      effort="1000"
      velocity="100" />
  </joint>


  <link
    name="RL_foot">
    <inertial>
      <origin
        xyz="-0.0065101 0.0000000 -0.0064928"
        rpy="0 0 0" />
      <mass
        value="0.00854471522743865" />
      <inertia
        ixx="0.0000011"
        ixy="0.0000000"
        ixz="0.0000003"
        iyy="0.0000011"
        iyz="0.0000000"
        izz="0.0000011" />
    </inertial>
    <visual>
      <origin
        xyz="0 0 0"
        rpy="0 0 0" />
      <geometry>
        <mesh
          filename="package://dog/meshes/RL_foot.STL" />
      </geometry>
    </visual>
    <collision>
      <origin
        xyz="0 0 0"
        rpy="0 0 0" />
      <geometry>
        <sphere radius="0.02"/>
      </geometry>
    </collision>
  </link>


  <joint
    name="RL_foot_fixed"
    type="fixed">
    <origin
      xyz="-9.305E-05 0.0261 -0.11865"
      rpy="0 0 0" />
    <parent
      link="RL_calf" />
    <child
      link="RL_foot" />
  </joint>


</robot>